Workbook
Name \0: #REF!
Name \a: #REF!
Name \b: #REF!
Name _____CAR1: #REF!
Name _____CAR2: #REF!
Name _____CAR3: #REF!
Name _____DES1: #REF!
Name _____DES2: #REF!
Name _____NOM01: #REF!
Name _____NOM02: #REF!
Name _____NOM03: #REF!
Name _____NOM1: #REF!
Name _____NOM2: #REF!
Name _____NOM3: #REF!
Name ____CAR1: #REF!
Name ____CAR2: #REF!
Name ____CAR3: #REF!
Name ____DES1: #REF!
Name ____DES2: #REF!
Name ____mo2: '[1]Analisis Hidraulicos'!#REF!
Name ____mo3: '[1]Analisis Hidraulicos'!#REF!
Name ____mo5: '[1]Analisis Hidraulicos'!#REF!
Name ____NOM01: #REF!
Name ____NOM02: #REF!
Name ____NOM03: #REF!
Name ____NOM1: #REF!
Name ____NOM2: #REF!
Name ____NOM3: #REF!
Name ____psi2: '[1]Analisis Hidraulicos'!#REF!
Name ____psi3: '[1]Analisis Hidraulicos'!#REF!
Name ____psi31: '[1]Analisis Hidraulicos'!#REF!
Name ____PSI4: '[2]Analisis Initarios '!#REF!
Name ____sub212: '[3]Analisis Electricos '!$B$466
Name ____sub26: '[3]Analisis Electricos '!$B$534
Name ____sub28: '[3]Analisis Electricos '!$B$330
Name ____sub288: '[3]Analisis Electricos '!$B$500
Name ____sub312: '[3]Analisis Electricos '!$B$432
Name ____sub34: '[3]Analisis Electricos '!$B$398
Name ____sub36: '[3]Analisis Electricos '!$B$364
Name ____sub38: '[3]Analisis Electricos '!$B$568
Name ___CAR1: #REF!
Name ___CAR2: #REF!
Name ___CAR3: #REF!
Name ___DES1: #REF!
Name ___DES2: #REF!
Name ___EST12: #REF!
Name ___mo1: '[4]1'!#REF!
Name ___mo2: '[1]Analisis Hidraulicos'!#REF!
Name ___mo3: '[1]Analisis Hidraulicos'!#REF!
Name ___mo5: '[1]Analisis Hidraulicos'!#REF!
Name ___MOD3: '[4]1'!#REF!
Name ___NOM01: #REF!
Name ___NOM02: #REF!
Name ___NOM03: #REF!
Name ___NOM1: #REF!
Name ___NOM2: #REF!
Name ___NOM3: #REF!
Name ___psi2: '[1]Analisis Hidraulicos'!#REF!
Name ___psi3: '[1]Analisis Hidraulicos'!#REF!
Name ___psi31: '[1]Analisis Hidraulicos'!#REF!

Sheet Tablero indicadores 2026
A1: PROCESOS ADMINISTRATIVOS / SEGURIDAD Y SALUD EN EL TRABAJO
A2: INDICADORES DE GESTION
A3: CODIGO | C3: RE-RH-37-SST | D3: NIVEL DE CLASIFICACIÓN | G3: USO INTERNO (NC2) | K3: VERSION | L3: 0.2
A5: INDICADORES DEL SISTEMA DE GESTION DE SEGURIDAD Y SALUD EN EL TRABAJO AÑO 2026
A6: TIPO DE INDICADOR | B6: NOMBRE INDICADOR | C6: DEFINICION | D6: COMO SE MIDE | F6: FUENTE DE INFORMACIÓN | G6: RESPONSABLE | H6: FRECUENCIA DE MEDICIÓN | I6: UNIDAD | J6: INFORMAR A | K6: INTERPRETACION | L6: META | M6: FORMULA | N6: RESULTADO 2017 | O6: RESULTADO 2018 | P6: RESULTADO 2019 | Q6: RESULTADO 2020 | R6: RESULTADO 2021 | S6: RESULTADO 2022 | T6: RESULTADO 2023 | U6: RESULTADO 2024 | V6: RESULTADO 2025 | W6: RESULTADO 2026
A7: ESTRUCTURA | B7: 1. Política de SST | C7: Divulgación de la política de SST | D7: Documento de la Política de SST firmada, divulgada y fechada. Cumplimiento de requisitos de norma. | F7: Politica SST | G7: Líder Funcional SG SST | H7: Anual | I7: Cumplimiento | J7: Gerencia General, Copasst | K7: El documento de la Política del SST esta firmada, divulgada y fechada. | L7: SI | M7: SI/NO | N7: SI | O7: SI | P7: SI | Q7: SI | R7: SI | S7: SI | T7: SI | U7: SI | V7: SI
A8: ESTRUCTURA | B8: 2. Objetivos y metas | C8: Objetivos y metas de seguridad divulgados | D8: Objetivos y metas de seguridad escritos y divulgados. | F8: SG-SST | G8: Líder Funcional SG SST | H8: Anual | I8: Cumplimiento | J8: Gerencia General, Copasst | K8: Los objetivos y metas de seguridad se encuentran escritos y divulgados. | L8: SI | M8: SI/NO | N8: SI | O8: SI | P8: SI | Q8: SI | R8: SI | S8: SI | T8: SI | U8: SI | V8: SI
A9: ESTRUCTURA | B9: 3. Plan de trabajo anual | C9: Actividades planeadas en el Plan de Trabajo anual en SST | D9: Cumplimiento de elaboración de plan de trabajo anual | F9: SG-SST | G9: Líder Funcional SG SST | H9: Mensual | I9: Cumplimiento | J9: Gerencia General, Copasst | K9: Se establece un plan de trabajo el cual incluye actividades para la gestión de los riesgos | L9: SI | M9: SI/NO | N9: SI | O9: SI | P9: SI | Q9: SI | R9: SI | S9: SI | T9: SI | U9: SI | V9: SI | W9: SI
A10: ESTRUCTURA | B10: 4. Responsabilidades | C10: Asignación de responsabilidades | D10: Evidencia de responsabilidades asignadas | F10: SG-SST | G10: Gerencia General - Líder funcional del SG SST | H10: Anual | I10: Cumplimiento | J10: Gerencia General, Copasst | K10: Se tienen responsabilidades asignadas en los diferentes niveles | L10: SI | M10: SI/NO | N10: SI | O10: SI | P10: SI | Q10: SI | R10: SI | S10: SI | T10: SI | U10: SI | V10: SI
A11: ESTRUCTURA | B11: 5. Recursos | C11: Asignación de recursos | D11: Presupuesto firmado por Gerencia General, donde se asignen los recursos fisicos, humanos, financieros y de otra indole. | F11: Presupuesto | G11: Gerencia General - Líder Funcional del SG SST | H11: Trimestral | I11: Cumplimiento | J11: Gerencia General, Copasst | K11: Se asignan los recursos para la implementación del SGSST | L11: SI | M11: SI/NO | N11: SI | O11: SI | P11: SI | Q11: SI | R11: SI | S11: SI | T11: SI | U11: SI | V11: SI
A12: ESTRUCTURA | B12: 6. Metodologia para identificación de peligros, evaluación y valoración de riesgos e Identificación de peligros y evaluación y valoración de reisgos con riesgos con participación de todos los niveles de la empresa. | C12: Método definido para la identificación de peligros e instrumento para reportar condiciones peligrosas. | D12: Cumplimiento de Método definido para la identificación de peligros. | F12: Procedimiento para la identificación de peligros e instrumento para reporte de condiciones/actos inseguras | G12: Líder Funcional SG SST | H12: Anual | I12: Cumplimiento | J12: Gerencia General, Copasst | K12: Se tiene definido un procedimiento para la identificación de peligros | L12: SI | M12: SI/NO | N12: SI | O12: SI | P12: SI | Q12: SI | R12: SI | S12: SI | T12: SI | U12: SI | V12: SI
A13: ESTRUCTURA | B13: 7. Conformación y funcionamiento del copasst y capacitación de los integrantes | C13: Conformación y Funcionamiento del COPASST | D13: Se cuenta con un COPASST en funcionamiento y con delegación de funciones. | F13: Actas de conformación y funcionamiento | G13: Copasst | H13: Mensual | I13: Cumplimiento | J13: Gerencia General, Copasst | K13: Se tiene definido un COPASST y funciona de acuerdo a la normatividad vigente | L13: SI | M13: SI/NO | N13: SI | O13: SI | P13: SI | Q13: SI | R13: SI | S13: SI | T13: SI | U13: SI | V13: SI | W13: SI
A14: ESTRUCTURA | B14: 8. Documentación | C14: Documentos que soportan el SGSST | D14: Cumplimiento con la documentación del SGSST | F14: SG-SST y soportes | G14: Gerente Líderes del area COPASST Comité de Convivencia laboral Líder funcional de SG SST | H14: Anual | I14: Cumplimiento | J14: Gerencia General, Copasst | K14: Informacion documentada de soportes para el SGSST | L14: SI | M14: SI/NO | N14: SI | O14: SI | P14: SI | Q14: SI | R14: SI | S14: SI | T14: SI | U14: SI | V14: SI
A15: ESTRUCTURA | B15: 9. Diagnostico de condiciones | C15: Procedimiento para efectuar el diagnostico de condiciones de salud de los trabajadores | D15: Evidencia del procedimiento | F15: Procedimiento para realizaciòn de examenes médicos y diagnóstico de las condiciones de salud | G15: Líder funcional del SGSST | H15: Anual | I15: Cumplimiento | J15: Gerencia General, Copasst | K15: Se tiene definido un procedimiento para el diagnóstico de condiciones de salud | L15: SI | M15: SI/NO | N15: SI | O15: SI | P15: SI | Q15: SI | R15: SI | S15: SI | T15: SI | U15: SI | V15: SI
A16: ESTRUCTURA | B16: 10. Plan de emergencias | C16: Existencia de plan de emergencia en las sedes | D16: N° de sedes con plan de emergencia/Nro total de sedes. *100 | F16: Plan de emergencias | G16: Líder Funcional SG SST | H16: Anual | I16: Número | J16: Gerencia General, Copasst | K16: Número de sedes con plan de emergencias | L16: 1 | M16: (8/8)*100 | N16: 0.5 | O16: 1 | P16: 1 | Q16: 1 | R16: 1 | S16: =(6/6)*100% -> 1 | T16: =(7/7) -> 1 | U16: =(8/8) -> 1 | V16: =(8/8) -> 1
A17: ESTRUCTURA | B17: 11. Plan de Capacitación en SST | C17: Documento del plan de capacitación en SST | D17: Evidencia de un plan de capacitacion en SST | F17: Plan de capacitación anual | G17: Líder Funcional SG SST | H17: Mensual | I17: Cumplimiento | J17: Gerencia General, Copasst | K17: Se tiene definido el plan de capacitación en SST | L17: SI | M17: SI/NO | N17: SI | O17: SI | P17: SI | Q17: SI | R17: SI | S17: SI | T17: SI | U17: SI | V17: SI | W17: SI
A18: TIPO DE INDICADOR | B18: NOMBRE INDICADOR | C18: DEFINICION | D18: COMO SE MIDE | F18: FUENTE DE INFORMACIÓN | G18: RESPONSABLE | H18: FRECUENCIA DE MEDICIÓN | I18: UNIDAD | J18: INFORMAR A | K18: INTERPRETACION | L18: META | M18: FORMULA | N18: RESULTADO 2017 | O18: RESULTADO 2018 | P18: RESULTADO 2019 | Q18: RESULTADO 2020 | R18: RESULTADO 2021 | S18: RESULTADO 2022 | T18: RESULTADO 2023 | U18: RESULTADO 2024 | V18: RESULTADO 2025 | W18: RESULTADO 2026
A19: PROCESO | B19: 1. Evaluacion Inicial | C19: Evaluación inicial del SG-SST | D19: SUMATORIA DE PORCENTAJE POR CADA UNO DE LOS ITEMS EVALUADOS QUE SE ENCUENTREN EN AVANZADO / NUMERO DE ITEMS EVALUADOS | F19: EVALUACIÓN INICIAL DEL SGSST | G19: Líder funcional del SGSST | H19: Anual | I19: Porcentaje | J19: Gerencia General, Copasst | K19: 95% de cumplimiento del SG SST | L19: 0.9 | M19: (10+15+19,26+10+5+10) | N19: 0.8025 | O19: 0.82 | P19: 0.9 | Q19: 0.89 | R19: 0.94 | S19: =SUM(10+15+19.5+27.5+10+5+10)% -> 0.97 | T19: =SUM(10+15+19+26+10+5+10)% -> 0.95 | U19: 0.95 | V19: =(8/8) -> 1
A20: PROCESO | B20: 2. Ejecución del plan de trabajo | C20: Ejecución del plan de trabajo en el SGSST | D20: (N° DE ACTIVIDADES DESARROLLADAS EN EL PERIODO EN EL PLAN/NRO DE ACTIVIDADES PROPUESTASEN EL PERIODO EN EL PLAN DE TRABAJO) X 100 | F20: PLAN ANUAL DE TRABAJO EN SST | G20: Líder Funcional SG SST | H20: Semestral | I20: Porcentaje | J20: Gerencia General, Copasst | K20: 58,48% de actividades cumplidas del plan de trabajo | L20: 0.9 | M20: (438/749)*100 | N20: 87.93% | O20: 0.89 | P20: 0.88 | Q20: 0.91 | R20: 0.97 | S20: =182/183 -> 0.99453552 | T20: =(403/703)*100% -> 0.57325747 | U20: 0.638 | V20: =(438/749) -> 0.58477971
A21: PROCESO | B21: 3. Ejecución del plan de capacitaciòn | C21: Capacitaciones realizadas en el año | D21: (N° DE CAPACITACIONES DESARROLLADAS EN EL PERIODOEN EL PLAN/NRO DE CAPACITACIONES PROPUESTAS EN EL PERIODO EN EL PLAN DE CAPACITACIÒN) X 100 | F21: PLAN DE CAPACITACION ANUAL | G21: Líder Funcional SG SST | H21: Semestral | I21: Porcentaje | J21: Gerencia General, Copasst | K21: 55% de capacitaciones realizadas del plan de capacitaciòn anual | L21: 0.9 | M21: (103/186)*100 | N21: 1 | O21: 0.9589 | P21: 0.95 | Q21: 0.9 | R21: 0.96 | S21: =157/157 -> 1 | T21: =(140/140)*100% -> 1 | U21: =(66/156) -> 0.42307692 | V21: =(103/186) -> 0.55376344
A22: PROCESO | B22: 4. Intervención de peligros identificados | C22: Intervención de los peligros identificados | D22: N° TOTAL DE PELIGROS INTERVENIDOS EN EL PERIODO/TOTAL DE PELIGROS IDENTIFICADOS | F22: INSPECCIONES DE SEGURIDAD MATRIZ DE RIESGOS INVESTIGACIONES DE AT REPORTES DEL COPASST | G22: Líder Funcional SG SST | H22: Semestral | I22: Porcentaje | J22: Gerencia General, Copasst | K22: 100% de peligros intervenidos | L22: 0.9 | M22: 7/3*100 | N22: 0.6857 | O22: 0.6857 | P22: 0.39 | Q22: 0.9 | R22: 1 | S22: =14/14 -> 1 | T22: =(5/7) -> 0.71428571 | U22: =(3/7) -> 0.42857143 | V22: =3/7 -> 0.42857143
A23: PROCESO | B23: 5. Condiciones de salud | C23: Evaluación de condiciones de salud y de trabajo | D23: CUMPLIMIENTO DE EVALUACION DE CONDICIONES DE SALUD | F23: EXAMENES MEDICOS, ENCUESTA CONDICIONES DE SALUD, | G23: Líder de Apoyo administrativo del SGSST | H23: Anual | I23: Cumplimiento | J23: Gerencia General, Copasst | K23: Se evaluan las condiciones de salud de los trabajadores | L23: SI | M23: SI/NO | N23: SI | O23: SI | P23: SI | Q23: SI | R23: SI | S23: SI | T23: SI | U23: SI | V23: SI
A24: PROCESO | B24: 6. Acciones preventivas, correctivas y de mejora | C24: Ejecución de acciones preventivas, correctivas y de mejora incluidas las generadas en la investigación de accidentes de trabajo | D24: (N° DE ACCIONES CORREGIDAS EN EL PERIODO/NRO DE ACCIONES ENCONTRADAS EN EL PERIODO) X 100 | F24: SGSST (INDICADORES, AT, EL, MATRIZ DE PELIGROS, AUDITORIA, REVISION POR LA DIRECCION) | G24: Líder Funcional SG SST | H24: Semestral | I24: Porcentaje | J24: Gerencia General, Copasst | K24: 100% acciones corregidas | L24: 0.9 | M24: (13/13)*100 | N24: 71.42% | O24: 71.42% | P24: 0.39 | Q24: 1 | R24: 1 | S24: =14/14 -> 1 | T24: =(6/6)*100% -> 1 | U24: =13/13 -> 1 | V24: =13/13 -> 1
A25: PROCESO | B25: 7. Mediciones ambientales | C25: Ejecución de mediciones ambientales ocupacionales | D25: (MEDICION AMBIENTAL REALIZADA/MEDICIONES AMBIENTALES DETECTADAS)*100 | F25: REGISTRO DE LOS ESTUDIOS AMBIENTALES | G25: Líder Funcional SG SST | H25: Anual | I25: Porcentaje | J25: Gerencia General, Copasst | K25: Ejecución de mediciones ambientales ocupacionales | L25: 0.9 | M25: (3/3)*100 | N25: 0.5 | O25: 0.66 | P25: 1 | Q25: 1 | R25: 1 | S25: 0 | T25: 1 | U25: =3/7 -> 0.42857143 | V25: =3/3 -> 1
A26: PROCESO | B26: 8. Vigilancia epidemiológica | C26: Desarrollo de los programas de vigilancia epidemiologica | D26: (NO. DE TRABAJADORES INTERVENIDOS EN EL SVE / NO. TRABAJADORES A INTERVENIR)*100 | F26: FORMATOS PROPIOS DE CADA SVE | G26: Líder Funcional SG SST | H26: Semestral | I26: Porcentaje | J26: Gerencia General, Copasst | K26: 100% de trabajadores incluidos en los SVE | L26: 0.9 | M26: (17%+53%+59%+68%+57%/5)*100 | N26: 1 | O26: 1 | P26: 1 | Q26: 1 | R26: 1 | S26: =1007/1007 -> 1 | T26: =(1099/1099) -> 1 | U26: =919/1041 -> 0.882805 | V26: =(17%+53%+59%+68%+57%)/5*(1) -> 0.508
A27: PROCESO | B27: 9. Investigación de accidentes, incidentes y enfermedades laborales | C27: Porcentaje de accidentes, incidentes y enfermedades laborales investigados | D27: N° DE AT, IT, EL INVESTIGADOS/NRO DE AT, IT, EL REPORTADOS | F27: REPORTE DE ACCIDENTES/INCIDENTES | G27: Gerente Líderes del area COPASST Comité de Convivencia laboral Líder funcional de SG SST | H27: Semestral | I27: Porcentaje | J27: Gerencia General, Copasst | K27: 100% de investigaciónes realizadas | L27: 0.9 | M27: (2*2)*100 | N27: 1 | O27: 1 | P27: 1 | Q27: 1 | R27: 1 | S27: =6/6 -> 1 | T27: =4/5 -> 0.8 | U27: 1 | V27: =(2/2) -> 1
A28: PROCESO | B28: 10. Plan de accidentalidad | C28: Ejecución del plan de intervención de la accidentalidad | D28: N° DE ACTIVIDADES DESARROLLADAS EN LA INTERVENCIÓN DE LOS RIESGOS PRIORITARIOS/ACTIVIDADES PROPUESTAS PARA LA INTERVENCIÓN DE LOS RIESGOS PRIORITARIOS | F28: ANÁLISIS DE LA ACCIDENTALIDAD INVESTIGACIÓN DE AT REPORTE DE IT, AT, EL | G28: Líderes del area COPASST Comité de Convivencia laboral Líder funcional de SG SST | H28: Semestral | I28: Porcentaje | J28: Gerencia General, Copasst | K28: 100% de actividades cumplidas del plan de intervención de riesgos | L28: 0.9 | M28: (6/6)*100 | N28: 1 | O28: 1 | P28: 1 | Q28: 1 | R28: 1 | S28: =6/6 -> 1 | T28: =4/5 -> 0.8 | U28: =5/5 -> 1 | V28: =(6/6) -> 1
A29: PROCESO | B29: 11. Estadisticas de EL, AT, IT y ausentismo laboral | C29: Registro Estadistico de AT, EL , y ausentismo laboral | D29: CUMPLIMIENTO DE REGISTRO DE ESTADISTICAS | F29: REGISTROS ESTADISTICOS | G29: Líder Funcional SG SST | H29: Trimestral | I29: Cumplimiento | J29: Gerencia General, Copasst | K29: Registro Estadistico realizado | L29: SI | M29: SI/NO | N29: SI | O29: SI | P29: SI | Q29: SI | R29: SI | S29: SI | T29: SI | U29: SI | V29: SI
A30: PROCESO | B30: 12. Plan de emergencias | C30: Ejecucion de los planes de emergencia en las sedes | D30: N° DE SEDES CON PLAN DE EMERGENCIAS / N° TOTAL DE SEDES *100 | F30: Plan de emergencias | G30: Líder Funcional SG SST | H30: Semestral | I30: Número | J30: Gerencia General, Copasst | K30: 100% de sedes con plan de emergencias | L30: 0.9 | M30: (9/12)*100 | N30: 0.5 | O30: 1 | P30: 1 | Q30: 1 | R30: 1 | S30: =7/7 -> 1 | T30: =6/8 -> 0.75 | U30: =8/8 -> 1 | V30: =(9/12) -> 0.75
A31: PROCESO | B31: Simulacros | C31: Procentaje de simulacros realizados | D31: N° DE SIMULACROS REALIZADOS/NRO DE SIMULACROS PROGRAMADOS | F31: PLAN ANUAL DE TRABAJO EN SST | G31: Gerente Jefes de Área COPASST Profesional en Salud Ocupacional, Brigada de emergencias | H31: Semestral | I31: Porcentaje | J31: Gerencia General, Copasst, Brigada de emergencias | K31: 100% de simulacros ejecutados | L31: 0.9 | M31: 1/12*100 | N31: 0.5 | O31: 0.66 | P31: 1 | Q31: 1 | R31: 1 | S31: =4/4 -> 1 | T31: =6/7 -> 0.85714286 | U31: =7/8 -> 0.875 | V31: =(1/12) -> 0.083333333
A32: PROCESO | B32: 13. Conservaciòn de documentos | C32: Evidencia de la conservación de documentos | D32: Conservación de documentos de manera controlada, garantizando que sean legibles, fácilmente identificables y accesibles. protegidos contra daño deterioro o pérdida. | F32: SGSST Y SOPORTES | G32: Líder Funcional SG SST | H32: Anual | I32: Cumplimiento | J32: Gerencia General, Copasst | K32: Se conservan los documentos de manera controlada, garantizando que sean legibles, fácilmente identificables y accesibles. protegidos contra daño. deterioro o pérdida. | L32: SI | M32: SI/NO | N32: SI | O32: SI | P32: SI | Q32: SI | R32: SI | S32: SI | T32: SI | U32: SI | V32: SI
A33: PROCESO | B33: 14.Riesgos de seguridad vial identeificados | C33: Verificar la cantidad de riesgos identificados al inicio del año vs final del año | D33: CANTIDAD DE RIESGOS IDENTIFICADOS AL FINAL DEL AÑO - CANTIDAD DE RIESGOS IDENTIFICADOS AL INICIO DEL AÑO | F33: PESV | G33: Líder Funcional SG SST | H33: Anual | I33: Porcentaje | J33: Gerencia General, Copasst | K33: Procedimiento de Identificación de Peligros, Evaluación y Valoración de Riesgos (IPEVR) Reportes de Actos y Condiciones Inseguras Auditorías de primera, segunda y tercera parte Informes ARL y otras partes interesadas Matriz o Herramienta para IPEVR | L33: 0.9 | M33: 35/35 | U33: 35/35 | V33: =35/35 -> 1
A34: PROCESO | B34: 15. Gestión de riesgos viales | C34: Identificar los riesgos viales con calificación alta a inicio de ñao vs los riesgos con calificación alta a final del año | D34: CANTIDAD DE RIESGOS CON VALORACIÓN ALTA AL FINAL DEL AÑO - CANTIDAD DE RIESGOS CON VALORACIÓN ALTA AL INICIO DEL AÑO | F34: PESV | G34: Líder Funcional SG SST | H34: Anual | I34: Porcentaje | J34: Gerencia General, Copasst | K34: Procedimiento de Identificación de Peligros, Evaluación y Valoración de Riesgos (IPEVR) Reportes de Actos y Condiciones Inseguras Auditorías de primera, segunda y tercera parte Informes ARL y otras partes interesadas Matriz o Herramienta para IPEVR | L34: 0.9 | V34: =3/3 -> 1
A35: TIPO DE INDICADOR | B35: NOMBRE INDICADOR | C35: DEFINICION | D35: COMO SE MIDE | F35: FUENTE DE INFORMACIÓN | G35: RESPONSABLE | H35: FRECUENCIA DE MEDICIÓN | I35: UNIDAD | J35: INFORMAR A | K35: INTERPRETACION | L35: META | M35: FORMULA | N35: RESULTADO 2017 | O35: RESULTADO 2018 | P35: RESULTADO 2019 | Q35: RESULTADO 2020 | R35: RESULTADO 2021 | S35: RESULTADO 2022 | T35: RESULTADO 2023 | U35: RESULTADO 2024 | V35: RESULTADO 2025 | W35: RESULTADO 2026
A36: RESULTADO | B36: 1. Requisitos Legales | C36: Cumplimiento de requisitos legales aplicables | D36: Verificaciòn de cumplimiento | F36: SG-SST | G36: Líder Funcional SG SST | H36: Mensual | I36: Cumplimiento | J36: Gerencia General, Copasst | K36: Se cumple con la normatividad legal vigente aplicable. | L36: 0.9 | M36: % | N36: SI | O36: SI | P36: SI | Q36: SI | R36: SI | S36: SI | T36: SI | U36: SI | V36: SI | W36: SI
A37: RESULTADO | B37: 2. Objetivos y metas | C37: Cumplimiento de Objetivos y metas en seguridad y salud. | D37: (No.de Objetivos y metas cumplidos/ No.de Objetivos y metas trazados) * 100 | F37: SG-SST | G37: Líder Funcional SG SST | H37: Semestral | I37: Cumplimiento | J37: Gerencia General, Copasst | K37: Se cumple con el 100% de los objetivos y metas trazados | L37: 0.9 | M37: (4/ 4 ) * 100 | N37: 0.4 | O37: 0.4 | P37: 0.2 | Q37: 0.25 | R37: 0.75 | S37: =4/4 -> 1 | T37: =4/4 -> 1 | U37: SI | V37: =(4/4) -> 1
A38: RESULTADO | B38: 3. Ejecución del plan de trabajo | C38: Ejecución del plan de trabajo en SST | D38: (N° DE ACTIVIDADES DESARROLLADAS EN EL PERIODO EN EL PLAN / NRO DE ACTIVIDADES PROPUESTASEN EL PERIODO EN EL PLAN DE TRABAJO) X 100 | F38: PLAN DE TRABAJO ANUAL EN SST | G38: Líder Funcional SG SST | H38: Semestral | I38: Porcentaje | J38: Gerencia General, Copasst | K38: 100% de actividades cumplidas del plan de trabajo | L38: 0.9 | M38: (438/749)*100 | N38: 87.93% | O38: 0.89 | P38: 0.88 | Q38: 0.91 | R38: 0.97 | S38: =182/183 -> 0.99453552 | T38: =178/181 -> 0.98342541 | U38: 0.638 | V38: =(438/749) -> 0.58477971
A39: RESULTADO | B39: 4. Evaluaciòn no conformidades | C39: Evaluación de las no conformidades detectadas en el seguimiento al plan de trabajo anual en seguridad y salud en el trabajo; | D39: (No. DE NO CONFORMIDADES EN EL PERIODO DEL PLAN DE TRABAJO ANUAL/ No DE ACTIVIDADES PLANEADAS PARA EL PERIODO)*100 | F39: PLAN DE TRABAJO ANUAL EN SST | G39: Líder Funcional SG SST | H39: Semestral | I39: Porcentaje | J39: Gerencia General, Copasst | K39: 0% de no conformidades detectadas en el seguimiento del plan de trabajo anual | L39: 0 | M39: 3/3*100 | N39: 0.4375 | O39: 0.1019 | P39: 0.13 | Q39: 0.085 | R39: 0.04 | S39: =1.8/183 -> 0.0098360656 | T39: =0/177% -> 0 | U39: =0/177% -> 0 | V39: =(3/3) -> 1
A40: RESULTADO | B40: 5. Acciones correctivas | C40: Muestra el porcentaje de acciones correctivas para las no conformidades resultantes de la revision por la direccion y auditorias (adicional ver indicadores de plan de accidentalidad e inpecciones). | D40: Acciones correctivas realizadas x 100 No de No Conformidades encontradas | F40: SG-SST | G40: Líder Funcional SG SST | H40: Anual | I40: Porcentaje | J40: Gerencia General, Copasst | K40: 100 % de las no conformidades tienen acciones correctivas | L40: 0.75 | M40: 13/13*100 | N40: 0.4375 | O40: 0.3793 | P40: 0.5769 | Q40: 1 | R40: 1 | S40: =15/15 -> 1 | T40: =15/15 -> 1 | U40: =13/13 -> 1 | V40: =13/13 -> 1
A41: RESULTADO | B41: 5.1 %Inspecciones realizadas | C41: Muestra el porcentaje de Inspecciones | D41: Número de inspecciones realizadas x 100 Número de inspecciones planeadas | F41: SG-SST | G41: Líder Funcional SG SST | H41: Trimestral | I41: Porcentaje | J41: Gerencia General, Copasst | K41: El 100% de las inspecciones planeadas se realizaron | L41: 0.9 | M41: (18/18 x 100 | N41: 0.5744 | O41: 0.5744 | P41: 1 | Q41: 0.75 | R41: 1 | S41: =68/68 -> 1 | T41: =52/52 -> 1 | U41: =18/18 -> 1 | V41: =18/18 -> 1
...

Sheet 1
A1: PROCESOS ADMINISTRATIVOS / SEGURIDAD Y SALUD EN EL TRABAJO
A2: INDICADORES DE GESTION
A3: CODIGO | C3: RE-RH-37-SST | D3: NIVEL DE CLASIFICACIÓN | G3: USO INTERNO (NC2) | K3: VERSION | L3: 0.2
A5: NOMBRE DEL INDICADOR | E5: ='Tablero indicadores 2026'!B7 -> 1. Política de SST
A7: PROCESO | E7: ='Tablero indicadores 2026'!A1 -> PROCESOS ADMINISTRATIVOS / SEGURIDAD Y SALUD EN EL TRABAJO | R7: META | T7: ='Tablero indicadores 2026'!W7 -> 0
A9: FORMULA | E9: ='Tablero indicadores 2026'!M7 -> SI/NO | R9: FRECUENCIA DE MEDICIÓN | T9: ='Tablero indicadores 2026'!H7 -> Anual
A11: UNIDAD | E11: ='Tablero indicadores 2026'!I7 -> Cumplimiento | R11: TIPO INDICADOR | T11: ='Tablero indicadores 2026'!A7 -> ESTRUCTURA
A13: RESPONSABLE MEDICIÓN | E13: ='Tablero indicadores 2026'!G7 -> Líder Funcional SG SST | R13: VIGENCIA | T13: 2026
A17: PARAMETROS | E17: Enero | F17: Febrero | G17: Marzo | H17: Abril | I17: Mayo | J17: Junio | K17: Julio | L17: Agosto | M17: Septiembre | N17: Octubre | O17: Noviembre | P17: Diciembre | R17: OBSERVACIONES: Documento de la política de SST firmada, divulgada y fechada.
A19: Numerador | G19: 1
A20: Denominador | G20: 1
A22: Rango Mayor (Meta) | G22: 1 | Q22: =#REF! -> #REF!
A24: Rango Menor | G24: 0
A26: Avance | G26: =G19/G20 -> 1
C31: ANÁLISIS | I31: ACCIÓN A SEGUIR
C32: El documento de la Política del SST se encuentre firmada, divulgada y fechada. | I32: Elaborar política de SST escrita, firmada, fechada y comunicada al copasst y a todos los trabajadores
C33: FECHA SEGUIMIENTO | I33: SEGUIMIENTO A LA IMPLEMENTACIÓN
C34: 46094 | I34: Se realiza socialización de la Política de seguridad y salud en el trabajo a todo el personal de SYC incluido el copasst en el mes de marzo y se publica en plataforma interna edocs, asi mismo se comparte por los diferentes medios de comunicación.
C35: RESPONSABLE
C36: ='Tablero indicadores 2026'!G7 -> Líder Funcional SG SST

Sheet 2
A1: PROCESOS ADMINISTRATIVOS / SEGURIDAD Y SALUD EN EL TRABAJO
A2: INDICADORES DE GESTION
A3: CODIGO | C3: RE-RH-37-SST | D3: NIVEL DE CLASIFICACIÓN | G3: USO INTERNO (NC2) | K3: VERSION | L3: 0.2
A5: NOMBRE DEL INDICADOR | E5: ='Tablero indicadores 2026'!B8 -> 2. Objetivos y metas
A7: PROCESO | E7: ='Tablero indicadores 2026'!A1 -> PROCESOS ADMINISTRATIVOS / SEGURIDAD Y SALUD EN EL TRABAJO | R7: META | T7: ='Tablero indicadores 2026'!A49:V50 -> #VALUE!
A9: FORMULA | E9: ='Tablero indicadores 2026'!M7 -> SI/NO | R9: FRECUENCIA DE MEDICIÓN | T9: ='Tablero indicadores 2026'!H8 -> Anual
A11: UNIDAD | E11: ='Tablero indicadores 2026'!I7 -> Cumplimiento | R11: TIPO INDICADOR | T11: ='Tablero indicadores 2026'!A7 -> ESTRUCTURA
A13: RESPONSABLE MEDICIÓN | E13: ='Tablero indicadores 2026'!G7 -> Líder Funcional SG SST | R13: VIGENCIA | T13: 2026
A17: PARAMETROS | E17: Enero | F17: Febrero | G17: Marzo | H17: Abril | I17: Mayo | J17: Junio | K17: Julio | L17: Agosto | M17: Septiembre | N17: Octubre | O17: Noviembre | P17: Diciembre | R17: OBSERVACIONES: Objetivos y metas de seguridad escritos y divulgados.
A19: Numerador | F19: 1
A20: Denominador | F20: 1
A22: Rango Mayor (Meta) | F22: 1 | Q22: =#REF! -> #REF!
A24: Rango Menor | F24: 0
A26: Avance | F26: =F19/F20 -> 1
C31: ANÁLISIS | I31: ACCIÓN A SEGUIR
C32: Definir los objetivos del Sistema de Gestión de SST de conformidad con la política de SST, los cuales deben ser claros, medibles, cuantificables y tener metas, coherentes con el plan de trabajo anual, compatibles con la normatividad vigente, se encuentran documentados, son comunicados a los trabajadores, son revisados y evaluados mínimo una vez al año, actualizados de ser necesario y se encuentran en documento firmado por el empleador | I32: Elaborar Objetivos para el 2025 de SST escritos, firmados, fechados y comunicados al copasst y a todos los trabajadores
C33: FECHA SEGUIMIENTO | I33: SEGUIMIENTO A LA IMPLEMENTACIÓN
C34: 46059 | I34: Se realiza socialización de los objetivos y metas del 2025 en seguridad y salud en el trabajo a todo el personal de SYC incluido el copasst en el mes de marzo y se publica en plataforma interna edocs y paraíso, asi mismo se comparte por los diferentes medios de comunicación.
C35: RESPONSABLE
C36: ='Tablero indicadores 2026'!G7 -> Líder Funcional SG SST

Sheet 3
A1: PROCESOS ADMINISTRATIVOS / SEGURIDAD Y SALUD EN EL TRABAJO
A2: INDICADORES DE GESTION
A3: CODIGO | C3: RE-RH-37-SST | D3: NIVEL DE CLASIFICACIÓN | G3: USO INTERNO (NC2) | K3: VERSION | L3: 0.2
A5: NOMBRE DEL INDICADOR | E5: ='Tablero indicadores 2026'!B9 -> 3. Plan de trabajo anual
A7: PROCESO | E7: ='Tablero indicadores 2026'!A1 -> PROCESOS ADMINISTRATIVOS / SEGURIDAD Y SALUD EN EL TRABAJO | R7: META | T7: ='Tablero indicadores 2026'!L20 -> 0.9
A9: FORMULA | E9: ='Tablero indicadores 2026'!M7 -> SI/NO | R9: FRECUENCIA DE MEDICIÓN | T9: ='Tablero indicadores 2026'!H9 -> Mensual
A11: UNIDAD | E11: ='Tablero indicadores 2026'!I7 -> Cumplimiento | R11: TIPO INDICADOR | T11: ='Tablero indicadores 2026'!A7 -> ESTRUCTURA
A13: RESPONSABLE MEDICIÓN | E13: ='Tablero indicadores 2026'!G7 -> Líder Funcional SG SST | R13: VIGENCIA | T13: 2026
A17: PARAMETROS | E17: Enero | F17: Febrero | G17: Marzo | H17: Abril | I17: Mayo | J17: Junio | K17: Julio | L17: Agosto | M17: Septiembre | N17: Octubre | O17: Noviembre | P17: Diciembre | R17: OBSERVACIONES: Cumplimiento de elaboración y ejecución del plan de trabajo anual.
A19: Numerador
A20: Denominador | E20: 33 | F20: 60
A22: Rango Mayor (Meta) | E22: 1 | F22: 1 | G22: 1 | H22: 1 | I22: 1 | J22: 1 | K22: 1 | L22: 1 | M22: 1 | N22: 1 | O22: 1 | P22: 1 | Q22: =#REF! -> #REF!
A24: Rango Menor | E24: 0 | F24: 0 | G24: 0 | H24: 0 | I24: 0 | J24: 0 | K24: 0 | L24: 0 | M24: 0 | N24: 0 | O24: 0 | P24: 0
A26: Avance | E26: =E19/E20 -> 0 | F26: =F19/F20 -> 0 | G26: =G19/G20 -> #DIV/0! | H26: =H19/H20 -> #DIV/0! | I26: =I19/I20 -> #DIV/0! | J26: =J19/J20 -> #DIV/0! | K26: =K19/K20 -> #DIV/0! | L26: =L19/L20 -> #DIV/0! | ... P26: =P19/P20 -> #DIV/0!
C31: ANÁLISIS | I31: ACCIÓN A SEGUIR
C32: Diseñar y definir un plan anual de trabajo para el cumplimiento del Sistema de Gestión de SST, el cual identifica los objetivos, metas, responsabilidades, recursos, cronograma de actividades, firmado por el empleador y el responsable del Sistema de Gestión de SST. | I32: Elaborar Plan anual para el 2026, donde se identifica los objetivos, metas, responsabilidades, recursos, cronograma de las actividades, firmados por el empleador y el responsable del SG SST.
C33: FECHA SEGUIMIENTO | I33: SEGUIMIENTO A LA IMPLEMENTACIÓN
C34: 46056 | F34: Elaboración plan de trabajo | I34: Se ha desarrollado el plan anual de trabajo para el año 2026 y se ha llevado a cabo la socialización con la alta dirección y se encuentra firmado por el empleador y el responsable del Sistema de Gestión de SST.
C35: 46080 | F35: Revisón y seguimiento al plan de trabajo
C36: 46112 | F36: Revisón y seguimiento al plan de trabajo
C37: 46142 | F37: Revisón y seguimiento al plan de trabajo
C38: 46171 | F38: Revisón y seguimiento al plan de trabajo
C39: 46203 | F39: Revisón y seguimiento al plan de trabajo
C40: 46234 | F40: Revisón y seguimiento al plan de trabajo
C41: 46265 | F41: Revisón y seguimiento al plan de trabajo
C42: 46295 | F42: Revisón y seguimiento al plan de trabajo
C43: 46325 | F43: Revisón y seguimiento al plan de trabajo
C44: 46356 | F44: Revisón y seguimiento al plan de trabajo
C45: 46360 | F45: Revisón y seguimiento al plan de trabajo
C46: RESPONSABLE
C47: ='Tablero indicadores 2026'!G7 -> Líder Funcional SG SST

Sheet 4
A1: PROCESOS ADMINISTRATIVOS / SEGURIDAD Y SALUD EN EL TRABAJO
A2: INDICADORES DE GESTION
A3: CODIGO | C3: RE-RH-37-SST | D3: NIVEL DE CLASIFICACIÓN | G3: USO INTERNO (NC2) | K3: VERSION | L3: 0.2
A5: NOMBRE DEL INDICADOR | E5: ='Tablero indicadores 2026'!B10 -> 4. Responsabilidades
A7: PROCESO | E7: ='Tablero indicadores 2026'!A1 -> PROCESOS ADMINISTRATIVOS / SEGURIDAD Y SALUD EN EL TRABAJO | R7: META | T7: ='Tablero indicadores 2026'!W7 -> 0
A9: FORMULA | E9: ='Tablero indicadores 2026'!M7 -> SI/NO | R9: FRECUENCIA DE MEDICIÓN | T9: ='Tablero indicadores 2026'!H10 -> Anual
A11: UNIDAD | E11: ='Tablero indicadores 2026'!I7 -> Cumplimiento | R11: TIPO INDICADOR | T11: ='Tablero indicadores 2026'!A7 -> ESTRUCTURA
A13: RESPONSABLE MEDICIÓN | E13: ='Tablero indicadores 2026'!G7 -> Líder Funcional SG SST | R13: VIGENCIA | T13: 2026
A17: PARAMETROS | E17: Enero | F17: Febrero | G17: Marzo | H17: Abril | I17: Mayo | J17: Junio | K17: Julio | L17: Agosto | M17: Septiembre | N17: Octubre | O17: Noviembre | P17: Diciembre | R17: OBSERVACIONES: Socializar con evidencia de responsabilidades asignadas tanto del responsable como los de toda la organización.
A19: Numerador | I19: 1
A20: Denominador | I20: 1
A22: Rango Mayor (Meta) | I22: 1 | Q22: =#REF! -> #REF!
A24: Rango Menor | I24: 0
A26: Avance | I26: =I19/I20 -> 1
C31: ANÁLISIS | I31: ACCIÓN A SEGUIR
C32: Asignar y documentar las responsabilidades específicas en el Sistema de Gestión SST a todos los niveles de la organización, para el desarrollo y mejora continua de dicho Sistema. | I32: Asignación de una persona que diseñe e implemente el Sistema de Gestión de SST Asignación de las responsabilidades en SST a todos los niveles de la organización
C33: FECHA SEGUIMIENTO | I33: SEGUIMIENTO A LA IMPLEMENTACIÓN
C34: 46083 | F34: Asignación de una persona que diseñe e implemente el Sistema de Gestión de SST | I34: _Se realiza la asignación de una persona que diseñe e implemente el Sistema de Gestión de SST. _Enviar a los diferentes niveles de la organización las responsabilidades específicas que cuentan dentro del Sistema de Gestión SST.
C35: 46171 | F35: Asignación de las responsabilidades en SSTa todos los niveles de la organización
C36: RESPONSABLE
C37: ='Tablero indicadores 2026'!G7 -> Líder Funcional SG SST

Sheet 5
A1: PROCESOS ADMINISTRATIVOS / SEGURIDAD Y SALUD EN EL TRABAJO
A2: INDICADORES DE GESTION
A3: CODIGO | C3: RE-RH-37-SST | D3: NIVEL DE CLASIFICACIÓN | G3: USO INTERNO (NC2) | K3: VERSION | L3: 0.2
A5: NOMBRE DEL INDICADOR | E5: ='Tablero indicadores 2026'!B11 -> 5. Recursos
A7: PROCESO | E7: ='Tablero indicadores 2026'!A1 -> PROCESOS ADMINISTRATIVOS / SEGURIDAD Y SALUD EN EL TRABAJO | R7: META | T7: ='Tablero indicadores 2026'!W7 -> 0
A9: FORMULA | E9: ='Tablero indicadores 2026'!M7 -> SI/NO | R9: FRECUENCIA DE MEDICIÓN | T9: TRIMESTRAL
A11: UNIDAD | E11: ='Tablero indicadores 2026'!I7 -> Cumplimiento | R11: TIPO INDICADOR | T11: ='Tablero indicadores 2026'!A7 -> ESTRUCTURA
A13: RESPONSABLE MEDICIÓN | E13: ='Tablero indicadores 2026'!G7 -> Líder Funcional SG SST | R13: VIGENCIA | T13: 2026
A17: PARAMETROS | E17: Enero | F17: Febrero | G17: Marzo | H17: Abril | I17: Mayo | J17: Junio | K17: Julio | L17: Agosto | M17: Septiembre | N17: Octubre | O17: Noviembre | P17: Diciembre | R17: OBSERVACIONES: Asignación de recursos para el sg sst, verificar con jefe de compras.
A19: Numerador | E19: 1 | G19: 1 | J19: 1
A20: Denominador | E20: 1 | G20: 1 | J20: 1 | M20: 1 | P20: 1
A22: Rango Mayor (Meta) | E22: 1 | G22: 1 | J22: 1 | M22: 1 | P22: 1 | Q22: =#REF! -> #REF!
A24: Rango Menor | E24: 0 | G24: 0 | J24: 0 | M24: 0 | P24: 0
A26: Avance | E26: =E19/E20 -> 1 | G26: =G19/G20 -> 1 | J26: =J19/J20 -> 1 | M26: =M19/M20 -> 0 | P26: =P19/P20 -> 0
C31: ANÁLISIS | I31: ACCIÓN A SEGUIR
C32: Definir y asignar el talento humano, los recursos financieros, técnicos y tecnológicos, requeridos para la implementación, mantenimiento y continuidad del Sistema de Gestión de SST. | I32: Asignar recursos para el Sistema de Gestión en SST firmado
C33: FECHA SEGUIMIENTO | I33: SEGUIMIENTO A LA IMPLEMENTACIÓN
C34: 46057 | F34: Definición y asignación de recursos para el SST | I34: Se ha constatado la asignación de recursos para el Sistema de Gestión en Seguridad y Salud en el Trabajo (SST). Se llevará a cabo una revisión trimestral de dicha asignación en concordancia con lo planificado por el área de compras, con el fin de efectuar un seguimiento. Además, se realizará un análisis semestral de la información recibida.
C35: 46111 | F35: Seguimiento a los recursos de acuerdo a lo planeado con el área de compras
C36: 46202 | F36: Seguimiento a los recursos de acuerdo a lo planeado con el área de compras
C37: 46295 | F37: Seguimiento a los recursos de acuerdo a lo planeado con el área de compras
C38: 46360 | F38: Seguimiento a los recursos de acuerdo a lo planeado con el área de compras
C39: RESPONSABLE
C40: ='Tablero indicadores 2026'!G7 -> Líder Funcional SG SST

Sheet 6
A1: PROCESOS ADMINISTRATIVOS / SEGURIDAD Y SALUD EN EL TRABAJO
A2: INDICADORES DE GESTION
A3: CODIGO | C3: RE-RH-37-SST | D3: NIVEL DE CLASIFICACIÓN | G3: USO INTERNO (NC2) | K3: VERSION | L3: 0.2
A5: NOMBRE DEL INDICADOR | E5: ='Tablero indicadores 2026'!B12 -> 6. Metodologia para identificación de peligros, evaluación y valoración de riesgos e Identificación de peligros y evaluación y valoración de reisgos con riesgos con participación de todos los niveles de la empresa.
A7: PROCESO | E7: ='Tablero indicadores 2026'!A1 -> PROCESOS ADMINISTRATIVOS / SEGURIDAD Y SALUD EN EL TRABAJO | R7: META | T7: ='Tablero indicadores 2026'!W7 -> 0
A9: FORMULA | E9: ='Tablero indicadores 2026'!M7 -> SI/NO | R9: FRECUENCIA DE MEDICIÓN | T9: ='Tablero indicadores 2026'!H10 -> Anual
A11: UNIDAD | E11: ='Tablero indicadores 2026'!I7 -> Cumplimiento | R11: TIPO INDICADOR | T11: ='Tablero indicadores 2026'!A7 -> ESTRUCTURA
A13: RESPONSABLE MEDICIÓN | E13: ='Tablero indicadores 2026'!G7 -> Líder Funcional SG SST | R13: VIGENCIA | T13: 2026
A17: PARAMETROS | E17: Enero | F17: Febrero | G17: Marzo | H17: Abril | I17: Mayo | J17: Junio | K17: Julio | L17: Agosto | M17: Septiembre | N17: Octubre | O17: Noviembre | P17: Diciembre | R17: OBSERVACIONES: Metodo definido para la identificación de peligros e instrumento para reportar condiciones peligrosas y participación de los trabajadores en la identificación de peligros, evaluación y valoración de los riesgos.
A19: Numerador | I19: 1
A20: Denominador | I20: 1
A22: Rango Mayor (Meta) | I22: 1 | Q22: =#REF! -> #REF!
A24: Rango Menor | I24: 0
A26: Avance | I26: =I19/I20 -> 1
C31: ANÁLISIS | I31: ACCIÓN A SEGUIR
C32: Definir y aplicar una metodología para la identificación de peligros y evaluación y valoración de los riesgos de origen físico, ergonómico o biomecánico, biológico, químico, de seguridad, público, psicosocial, entre otros, con alcance sobre todos los procesos, actividades rutinarias y no rutinarias, maquinaria y equipos en todos los centros de trabajo y respecto de todos los trabajadores independientemente de su forma de vinculación y/o contratación. Identificar con base en la valoración de los riesgos, aquellos que son prioritarios. | I32: _Solicitar el documento que contiene la metodología. _ Verificar que se realiza la identificación de peligros, evaluación y valoración de los riesgos conforme a la metodología definida de acuerdo con el criterio y con la participación de los trabajadores, seleccionando de manera aleatoria algunas de las actividades identificadas. _Confrontar mediante observación directa durante el recorrido a las instalaciones de la empresa la identificación de peligros.
C33: Identificación de peligros y evaluación y valoración de riesgos con participación de todos los niveles de la empresa | I33: Realizar la identificación de peligros y evaluación y valoración de los riesgos con participación de los trabajadores de todos los niveles de la empresa y actualizarla como mínimo una (1) vez al año y cada vez que ocurra un accidente de trabajo mortal o un evento catastrófico en la empresa o cuando se presenten cambios en los procesos, en las instalaciones, o maquinaria o equipos.
C34: FECHA SEGUIMIENTO | I34: SEGUIMIENTO A LA IMPLEMENTACIÓN
C35: 46300 | F35: Revisión de documento que contiene la metodología IPERV | I35: _ Revisar si la identificación de peligros, evaluación y valoración de los riesgos se debe actualizar de acuerdo al criterio y participación de los trabajadores. _ Realizar la identificación de peligro y valoración de los riesgos de acuerdo a la participación de los trabajadores de todos los niveles de la empresa.
C36: 46330 | F36: Realizar la participación de los trabajadores de todos los niveles de la empresa.
C37: RESPONSABLE
C38: ='Tablero indicadores 2026'!G7 -> Líder Funcional SG SST

Sheet 7
A1: PROCESOS ADMINISTRATIVOS / SEGURIDAD Y SALUD EN EL TRABAJO
A2: INDICADORES DE GESTION
A3: CODIGO | C3: RE-RH-37-SST | D3: NIVEL DE CLASIFICACIÓN | G3: USO INTERNO (NC2) | K3: VERSION | L3: 0.2
A5: NOMBRE DEL INDICADOR | E5: ='Tablero indicadores 2026'!B13 -> 7. Conformación y funcionamiento del copasst y capacitación de los integrantes
A7: PROCESO | E7: ='Tablero indicadores 2026'!A1 -> PROCESOS ADMINISTRATIVOS / SEGURIDAD Y SALUD EN EL TRABAJO | R7: META | T7: ='Tablero indicadores 2026'!W7 -> 0
A9: FORMULA | E9: ='Tablero indicadores 2026'!M7 -> SI/NO | R9: FRECUENCIA DE MEDICIÓN | T9: ='Tablero indicadores 2026'!H13 -> Mensual
A11: UNIDAD | E11: ='Tablero indicadores 2026'!I7 -> Cumplimiento | R11: TIPO INDICADOR | T11: ='Tablero indicadores 2026'!A7 -> ESTRUCTURA
A13: RESPONSABLE MEDICIÓN | E13: ='Tablero indicadores 2026'!G7 -> Líder Funcional SG SST | R13: VIGENCIA | T13: 2026
A17: PARAMETROS | E17: Enero | F17: Febrero | G17: Marzo | H17: Abril | I17: Mayo | J17: Junio | K17: Julio | L17: Agosto | M17: Septiembre | N17: Octubre | O17: Noviembre | P17: Diciembre | R17: OBSERVACIONES: Se cuenta con un COPASST en funcionamiento y con delegación de funciones.
A19: Numerador | E19: 1 | F19: 1 | G19: 1 | H19: 1 | I19: 1 | J19: 1
A20: Denominador | E20: 1 | F20: 1 | G20: 1 | H20: 1 | I20: 1 | J20: 1 | K20: 1 | L20: 1 | M20: 1 | N20: 1 | O20: 1 | P20: 1
A22: Rango Mayor (Meta) | E22: 1 | F22: 1 | G22: 1 | H22: 1 | I22: 1 | J22: 1 | K22: 1 | L22: 1 | M22: 1 | N22: 1 | O22: 1 | P22: 1 | Q22: =#REF! -> #REF!
A24: Rango Menor | E24: 0 | F24: 0 | G24: 0 | H24: 0 | I24: 0 | J24: 0 | K24: 0 | L24: 0 | M24: 0 | N24: 0 | O24: 0 | P24: 0
A26: Avance | E26: =E19/E20 -> 1 | F26: =F19/F20 -> 1 | G26: =G19/G20 -> 1 | H26: =H19/H20 -> 1 | I26: =I19/I20 -> 1 | J26: =J19/J20 -> 1 | K26: =K19/K20 -> 0 | L26: =L19/L20 -> 0 | ... P26: =P19/P20 -> 0
C31: ANÁLISIS | I31: ACCIÓN A SEGUIR
C32: Conformar y garantizar el funcionamiento del Comité paritario de Seguridad y Salud en el Trabajo y capacitar a los (sic) integrantes del copasst para el cumplimiento efectivo de las responsabilidades que le asigna la ley. | I32: _ Solicitarlos soportes de convocatoria, elección, conformación del comité Paritario de Seguridad y Salud en el trabajo y el acta de constitución. _Constatar si es igual el número de representante del empleador y de los trabajadores y revisar si el acta de conformación se encuentra vigente. _ Solicitar las actas de reunión mensuales del último año del Comité Paritario y verificar el cumplimiento de sus funciones. _Solicitar documentos que evidencien las actividades de capacitación brindada a los integrantes del COPASST.
C33: FECHA SEGUIMIENTO | I33: SEGUIMIENTO A LA IMPLEMENTACIÓN
C34: 46052 | F34: Revisión de acta de reunión mes enero | I34: Acta realizada
C35: 46080 | F35: Revisión de acta de reuinión mes febrero y capacitación de funciones y responsabilidades
C36: 46112 | F36: Revisión acta de reunión y evaluación identificación de peligros y valoración de riesgos
C37: 46142 | F37: Revisión acta de reunión y evaluación identificación de peligros y valoración de riesgos
C38: 46171 | F38: Revisión acta de reunión y evaluación identificación de peligros y valoración de riesgos
C39: 46203 | F39: Revisión acta de reunión y evaluación identificación de peligros y valoración de riesgos
C40: 46234 | F40: Revisión acta de reunión y evaluación identificación de peligros y valoración de riesgos
C41: 46265 | F41: Revisión acta de reunión y evaluación identificación de peligros y valoración de riesgos
C42: 46295 | F42: Revisión acta de reunión y evaluación identificación de peligros y valoración de riesgos
C43: 46325 | F43: Revisión acta de reunión y evaluación identificación de peligros y valoración de riesgos
C44: 46356 | F44: Revisión acta de reunión y evaluación identificación de peligros y valoración de riesgos
C45: 46387
C46: RESPONSABLE
C47: ='Tablero indicadores 2026'!G7 -> Líder Funcional SG SST

Sheet 8
A1: PROCESOS ADMINISTRATIVOS / SEGURIDAD Y SALUD EN EL TRABAJO
A2: INDICADORES DE GESTION
A3: CODIGO | C3: RE-RH-37-SST | D3: NIVEL DE CLASIFICACIÓN | G3: USO INTERNO (NC2) | K3: VERSION | L3: 0.2
A5: NOMBRE DEL INDICADOR | E5: ='Tablero indicadores 2026'!B14 -> 8. Documentación
A7: PROCESO | E7: ='Tablero indicadores 2026'!A1 -> PROCESOS ADMINISTRATIVOS / SEGURIDAD Y SALUD EN EL TRABAJO | R7: META | T7: ='Tablero indicadores 2026'!W7 -> 0
A9: FORMULA | E9: ='Tablero indicadores 2026'!M7 -> SI/NO | R9: FRECUENCIA DE MEDICIÓN | T9: ='Tablero indicadores 2026'!H10 -> Anual
A11: UNIDAD | E11: ='Tablero indicadores 2026'!I7 -> Cumplimiento | R11: TIPO INDICADOR | T11: ='Tablero indicadores 2026'!A7 -> ESTRUCTURA
A13: RESPONSABLE MEDICIÓN | E13: ='Tablero indicadores 2026'!G7 -> Líder Funcional SG SST | R13: VIGENCIA | T13: 2026
A17: PARAMETROS | E17: Enero | F17: Febrero | G17: Marzo | H17: Abril | I17: Mayo | J17: Junio | K17: Julio | L17: Agosto | M17: Septiembre | N17: Octubre | O17: Noviembre | P17: Diciembre | R17: OBSERVACIONES: Cumplimiento con la documentación del SGSST.
A19: Numerador
A20: Denominador | P20: 1
A22: Rango Mayor (Meta) | P22: 1 | Q22: =#REF! -> #REF!
A24: Rango Menor | P24: 0
A26: Avance | P26: =P19/P20 -> 0
C31: ANÁLISIS | I31: ACCIÓN A SEGUIR
C32: Contar con un sistema de archivoy retención documental, para los registros y documentos que soportane el Sistema de Gestión de SST | I32: _Constatar la existencia de un sistema de archivo y retención documental, para los registros y documentos que soportan el Sistema de Gestión de SST. _Verificar mediante muestreo que los registros y documentos sean legibles (entendible para el lector objeto), fácilmente identificables y accesibles (para todos los que estén vinculados con cada documento en particular), protegidos contra daño y pérdida
C33: FECHA SEGUIMIENTO | I33: SEGUIMIENTO A LA IMPLEMENTACIÓN
C34: 46360 | F34: Revisar si a existido cambio en el procedimiento control de documentos área de calidad y constatar el archivo de retención documental por 20 años. | I34: Revisar que el sistema de archivo y retención documental, para los registros y documentos que soportan el Sistema de Gestión de SST no tenga ninguna novedad.
C35: RESPONSABLE
C36: ='Tablero indicadores 2026'!G7 -> Líder Funcional SG SST

Sheet 9
A1: PROCESOS ADMINISTRATIVOS / SEGURIDAD Y SALUD EN EL TRABAJO
A2: INDICADORES DE GESTION
A3: CODIGO | C3: RE-RH-37-SST | D3: NIVEL DE CLASIFICACIÓN | G3: USO INTERNO (NC2) | K3: VERSION | L3: 0.2
A5: NOMBRE DEL INDICADOR | E5: ='Tablero indicadores 2026'!B15 -> 9. Diagnostico de condiciones
A7: PROCESO | E7: ='Tablero indicadores 2026'!A1 -> PROCESOS ADMINISTRATIVOS / SEGURIDAD Y SALUD EN EL TRABAJO | R7: META | T7: ='Tablero indicadores 2026'!W7 -> 0
A9: FORMULA | E9: ='Tablero indicadores 2026'!M7 -> SI/NO | R9: FRECUENCIA DE MEDICIÓN | T9: ='Tablero indicadores 2026'!H10 -> Anual
A11: UNIDAD | E11: ='Tablero indicadores 2026'!I7 -> Cumplimiento | R11: TIPO INDICADOR | T11: ='Tablero indicadores 2026'!A7 -> ESTRUCTURA
A13: RESPONSABLE MEDICIÓN | E13: ='Tablero indicadores 2026'!G7 -> Líder Funcional SG SST | R13: VIGENCIA | T13: 2026
A17: PARAMETROS | E17: Enero | F17: Febrero | G17: Marzo | H17: Abril | I17: Mayo | J17: Junio | K17: Julio | L17: Agosto | M17: Septiembre | N17: Octubre | O17: Noviembre | P17: Diciembre | R17: OBSERVACIONES: Procedimiento para realización de examenes medicos y diagnosticos de la condiciones de salud.
A19: Numerador
A20: Denominador | P20: 1
A22: Rango Mayor (Meta) | P22: 1 | Q22: =#REF! -> #REF!
A24: Rango Menor | P24: 0
A26: Avance | P26: =P19/P20 -> 0
C31: ANÁLISIS | I31: ACCIÓN A SEGUIR
C32: Procedimiento para efectuar el diagnostico de condiciones de salud de los trabajadores | I32: Evidencia del procedimiento para realizaciòn de examenes médicos y diagnóstico de las condiciones de salud
C33: FECHA SEGUIMIENTO | I33: SEGUIMIENTO A LA IMPLEMENTACIÓN
C34: 46360 | F34: Revisar si a existido cambio en el procedimiento control de documentos área de calidad y constatar el archivo de retención documental por 20 años. | I34: Revisar la evidencia del procedimiento para la realización de examenes medicos y diagnostico de con las condiciones de salud.
C35: RESPONSABLE
C36: ='Tablero indicadores 2026'!G7 -> Líder Funcional SG SST

Sheet 10
A1: PROCESOS ADMINISTRATIVOS / SEGURIDAD Y SALUD EN EL TRABAJO
A2: INDICADORES DE GESTION
A3: CODIGO | C3: RE-RH-37-SST | D3: NIVEL DE CLASIFICACIÓN | G3: USO INTERNO (NC2) | K3: VERSION | L3: 0.2
A5: NOMBRE DEL INDICADOR | E5: ='Tablero indicadores 2026'!B16 -> 10. Plan de emergencias
A7: PROCESO | E7: ='Tablero indicadores 2026'!A1 -> PROCESOS ADMINISTRATIVOS / SEGURIDAD Y SALUD EN EL TRABAJO | R7: META | T7: ='Tablero indicadores 2026'!W7 -> 0
A9: FORMULA | E9: ='Tablero indicadores 2026'!M7 -> SI/NO | R9: FRECUENCIA DE MEDICIÓN | T9: ='Tablero indicadores 2026'!H10 -> Anual
A11: UNIDAD | E11: ='Tablero indicadores 2026'!I16 -> Número | R11: TIPO INDICADOR | T11: ='Tablero indicadores 2026'!A7 -> ESTRUCTURA
A13: RESPONSABLE MEDICIÓN | E13: ='Tablero indicadores 2026'!G7 -> Líder Funcional SG SST | R13: VIGENCIA | T13: 2026
A17: PARAMETROS | E17: Enero | F17: Febrero | G17: Marzo | H17: Abril | I17: Mayo | J17: Junio | K17: Julio | L17: Agosto | M17: Septiembre | N17: Octubre | O17: Noviembre | P17: Diciembre | R17: OBSERVACIONES: Existencia de plan de emergencia en las sedes.
A19: Numerador | J19: 9
A20: Denominador | J20: 12 | O20: 8
A22: Rango Mayor (Meta) | J22: 1 | O22: 1 | Q22: =#REF! -> #REF!
A24: Rango Menor | J24: 0 | O24: 0
A26: Avance | J26: =J19/J20 -> 0.75 | O26: =O19/O20 -> 0
C31: ANÁLISIS | I31: ACCIÓN A SEGUIR
C32: _Elaborar un plan de prevención, preparación y respuesta ante emergencias que identifique las amenazas, evalúe y analice la vulnerabilidad. _Como mínimo el plan debe incluir: planos de las instalaciones que identifican áreas y salidas de emergencia, así como la señalización, realización de simulacros como mínimo una (1) vez al año. _El plan debe tener en cuenta todas las jornadas de trabajo en todos los centros de trabajo y debe ser divulgado. | I32: _Solicitar el plan de prevención, preparación y respuesta ante emergencias y constatar evidencias de su divulgación. _Verificar si existen los planos de las instalaciones que identifican áreas y salidas de emergencia y verificar si existe la debida señalización de la empresa. _Verificar los soportes que evidencien la realización de los simulacros y análisis de los mismos y validar que las recomendaciones emitidas con base en dicho análisis hayan sido tenidas en cuenta en el mejoramiento del plan de emergencias.
C33: FECHA SEGUIMIENTO | I33: SEGUIMIENTO A LA IMPLEMENTACIÓN
C34: 46178 | F34: Divulgación del plan de emergencias
C35: 46304 | F35: Simulacro a nivel nacional y participación | I35: Verificar los soportes que evidencien la realización de los simulacros y divulgación del plan de emergencias en las diferentes sedes.
C36: RESPONSABLE
C37: ='Tablero indicadores 2026'!G7 -> Líder Funcional SG SST

Sheet 11
A1: PROCESOS ADMINISTRATIVOS / SEGURIDAD Y SALUD EN EL TRABAJO
A2: INDICADORES DE GESTION
A3: CODIGO | C3: RE-RH-37-SST | D3: NIVEL DE CLASIFICACIÓN | G3: USO INTERNO (NC2) | K3: VERSION | L3: 0.2
A5: NOMBRE DEL INDICADOR | E5: ='Tablero indicadores 2026'!B17 -> 11. Plan de Capacitación en SST
A7: PROCESO | E7: ='Tablero indicadores 2026'!A1 -> PROCESOS ADMINISTRATIVOS / SEGURIDAD Y SALUD EN EL TRABAJO | R7: META | T7: ='Tablero indicadores 2026'!W7 -> 0
A9: FORMULA | E9: SI/NO | R9: FRECUENCIA DE MEDICIÓN | T9: ='Tablero indicadores 2026'!H17 -> Mensual
A11: UNIDAD | E11: ='Tablero indicadores 2026'!I7 -> Cumplimiento | R11: TIPO INDICADOR | T11: ='Tablero indicadores 2026'!A7 -> ESTRUCTURA
A13: RESPONSABLE MEDICIÓN | E13: ='Tablero indicadores 2026'!G7 -> Líder Funcional SG SST | R13: VIGENCIA | T13: 2026
A17: PARAMETROS | E17: Enero | F17: Febrero | G17: Marzo | H17: Abril | I17: Mayo | J17: Junio | K17: Julio | L17: Agosto | M17: Septiembre | N17: Octubre | O17: Noviembre | P17: Diciembre | R17: OBSERVACIONES:Evidencia de un plan de capacitacion en SST
A19: Numerador | E19: 5 | F19: 18 | G19: 22 | H19: 42 | I19: 17 | J19: 20 | K19: 16
A20: Denominador | E20: 5 | F20: 18 | G20: 22 | H20: 42 | I20: 21 | J20: 25 | K20: 16 | L20: 20 | M20: 24 | N20: 15 | O20: 9 | P20: 6
A22: Rango Mayor (Meta) | E22: 1 | F22: 1 | G22: 1 | H22: 1 | I22: 1 | J22: 1 | K22: 1 | L22: 1 | M22: 1 | N22: 1 | O22: 1 | P22: 1 | Q22: =#REF! -> #REF!
A24: Rango Menor | E24: 0 | F24: 0 | G24: 0 | H24: 0 | I24: 0 | J24: 0 | K24: 0 | L24: 0 | M24: 0 | N24: 0 | O24: 0 | P24: 0
A26: Avance | E26: =E19/E20 -> 1 | F26: =F19/F20 -> 1 | G26: =G19/G20 -> 1 | H26: =H19/H20 -> 1 | I26: =I19/I20 -> 0.80952381 | J26: =J19/J20 -> 0.8 | K26: =K19/K20 -> 1 | L26: =L19/L20 -> 0 | ... P26: =P19/P20 -> 0
C32: ANÁLISIS | I32: ACCIÓN A SEGUIR
C33: Elaborar y ejecutar el programa de capacitación en promoción y prevención, que incluye lo referente a los peligros/riesgos prioritarios y las medidas de prevención y control, extensivo a todos los niveles de la organización. | I33: Solicitar el programa de capacitación anual y la matriz de identificación de peligros y verificar que el mismo esté dirigido a los peligros ya identificados y esté acorde con la evaluación y control de los riesgos y/o necesidades en Seguridad y Salud en el Trabajo. Solicitar los documentos que evidencien el cumplimiento del programa de capacitación.
C34: FECHA SEGUIMIENTO | I34: SEGUIMIENTO A LA IMPLEMENTACIÓN
C35: 46056 | F35: Verificar que las capacitaciónes se halla ejecutado | I35: Se verifica la realización de la capacitación planeada
C36: 46080 | F36: Verificar que las capacitaciónes se halla ejecutado | I36: Se verifica la realización de la capacitación planeada
C37: 46112 | F37: Verificar que las capacitaciónes se halla ejecutado | I37: Se verifica la realización de la capacitación planeada
C38: 46142 | F38: Verificar que las capacitaciónes se halla ejecutado | I38: Se verifica la realización de la capacitación planeada
C39: 46171 | F39: Verificar que las capacitaciónes se halla ejecutado | I39: Se verifica la realización de la capacitación planeada
C40: 46203 | F40: Verificar que las capacitaciónes se halla ejecutado | I40: Se verifica la realización de la capacitación planeada
C41: 46234 | F41: Verificar que las capacitaciónes se halla ejecutado
C42: 46265 | F42: Verificar que las capacitaciónes se halla ejecutado
C43: 46295 | F43: Verificar que las capacitaciónes se halla ejecutado
C44: 46325 | F44: Verificar que las capacitaciónes se halla ejecutado
C45: 46356 | F45: Verificar que las capacitaciónes se halla ejecutado
C46: 46360 | F46: Verificar que las capacitaciónes se halla ejecutado
C47: RESPONSABLE | I47: Ejecutar el programa de capacitación acorde a los peligros/riesgos prioritatios y las medidas de prevención y control de la empresa
C48: ='Tablero indicadores 2026'!G8 -> Líder Funcional SG SST

Sheet 1.
A1: PROCESOS ADMINISTRATIVOS / SEGURIDAD Y SALUD EN EL TRABAJO
A2: INDICADORES DE GESTION
A3: CODIGO | C3: RE-RH-37-SST | D3: NIVEL DE CLASIFICACIÓN | G3: USO INTERNO (NC2) | K3: VERSION | L3: 0.2
A5: NOMBRE DEL INDICADOR | E5: ='Tablero indicadores 2026'!B19 -> 1. Evaluacion Inicial
A7: PROCESO | E7: ='Tablero indicadores 2026'!A1 -> PROCESOS ADMINISTRATIVOS / SEGURIDAD Y SALUD EN EL TRABAJO | R7: META | T7: ='Tablero indicadores 2026'!L19 -> 0.9
A9: FORMULA | E9: ='Tablero indicadores 2026'!M7 -> SI/NO | R9: FRECUENCIA DE MEDICIÓN | T9: ='Tablero indicadores 2026'!H19 -> Anual
A11: UNIDAD | E11: ='Tablero indicadores 2026'!I19 -> Porcentaje | R11: TIPO INDICADOR | T11: ='Tablero indicadores 2026'!A19 -> PROCESO
A13: RESPONSABLE MEDICIÓN | E13: ='Tablero indicadores 2026'!G7 -> Líder Funcional SG SST | R13: VIGENCIA | T13: 2026
A17: PARAMETROS | E17: Enero | F17: Febrero | G17: Marzo | H17: Abril | I17: Mayo | J17: Junio | K17: Julio | L17: Agosto | M17: Septiembre | N17: Octubre | O17: Noviembre | P17: Diciembre | R17: OBSERVACIONES: Sumatoria de porcentaje por cada uno de los items evaluados que se encuentren en avanzado / numero de items evaluados.
A19: Numerador
A20: Denominador | P20: 100
A22: Rango Mayor (Meta) | P22: 1 | Q22: =#REF! -> #REF!
A24: Rango Menor | P24: 0
A26: Avance | P26: =P19/P20 -> 0
C32: ANÁLISIS | I32: ACCIÓN A SEGUIR
C33: _Realizar la evaluación inicial del Sistema de Gestión de SST, identificando las prioridades para establecer el plan de trabajo anual o para la actualización del existente. _Debe ser realizada por el responsable del Sistema de Gestión de SST o contratada por la empresa con personal externo con licencia en Seguridad y Salud en el Trabajo. | I33: Solicitar la evaluación inicial del Sistema de Gestión de SST mediante la matriz legal, matriz de peligros y evaluación de riesgos, verificación de controles, lista de asistencia a capacitaciones, análisis de puestos de trabajo, exámenes médicos de ingreso y periódicos y seguimiento de indicadores, entre otros.
C34: FECHA SEGUIMIENTO | I34: SEGUIMIENTO A LA IMPLEMENTACIÓN
C35: 45997 | F35: Realizar evaluación Final SST | I35: Se realiza la evaluación final generando acciones de mejora en los siguientes items : 4.1.4 Realización mediciones ambientales, químicos, físicos y biológicos y 3.1.7 Estilos de vida y entornos saludables (controles tabaquismo, alcoholismo, farmacodependencia y otros)
C36: 46024 | F36: Realizar evaluación Inical SST
C37: RESPONSABLE | I37: Verificar que se realicen las acciones de mejora de acuerdo al resultado de los estandares
C38: ='Tablero indicadores 2026'!G8 -> Líder Funcional SG SST

Sheet 2.
A1: PROCESOS ADMINISTRATIVOS / SEGURIDAD Y SALUD EN EL TRABAJO
A2: INDICADORES DE GESTION
A3: CODIGO | C3: RE-RH-37-SST | D3: NIVEL DE CLASIFICACIÓN | G3: USO INTERNO (NC2) | K3: VERSION | L3: 0.2
A5: NOMBRE DEL INDICADOR | E5: ='Tablero indicadores 2026'!B20 -> 2. Ejecución del plan de trabajo
A7: PROCESO | E7: ='Tablero indicadores 2026'!A1 -> PROCESOS ADMINISTRATIVOS / SEGURIDAD Y SALUD EN EL TRABAJO | R7: META | T7: ='Tablero indicadores 2026'!L20 -> 0.9
A9: FORMULA | E9: ='Tablero indicadores 2026'!M7 -> SI/NO | R9: FRECUENCIA DE MEDICIÓN | T9: ='Tablero indicadores 2026'!H20 -> Semestral
A11: UNIDAD | E11: ='Tablero indicadores 2026'!I20 -> Porcentaje | R11: TIPO INDICADOR | T11: ='Tablero indicadores 2026'!A19 -> PROCESO
A13: RESPONSABLE MEDICIÓN | E13: ='Tablero indicadores 2026'!G7 -> Líder Funcional SG SST | R13: VIGENCIA | T13: 2026
A17: PARAMETROS | E17: Enero | F17: Febrero | G17: Marzo | H17: Abril | I17: Mayo | J17: Junio | K17: Julio | L17: Agosto | M17: Septiembre | N17: Octubre | O17: Noviembre | P17: Diciembre | R17: OBSERVACIONES: ( N° de actividades desarrolladas en el periodo en el plan / nro de actividades propuestas en el periodo en el plan de trabajo) x 100
A19: Numerador
A20: Denominador | J20: 353 | P20: 390
A22: Rango Mayor (Meta) | J22: 1 | P22: 1 | Q22: =#REF! -> #REF!
A24: Rango Menor | J24: 0 | P24: 0
A26: Avance | J26: =J19/J20 -> 0 | P26: =P19/P20 -> 0
C32: ANÁLISIS | I32: ACCIÓN A SEGUIR
C33: Diseñar y definir un plan anual de trabajo para el cumplimiento del Sistema de Gestión de SST, el cual identifica los objetivos, metas, responsabilidades, recursos, cronograma de actividades, firmado por el empleador y el responsable del Sistema de Gestión de SST. | I33: Solicitar el plan de trabajo anual. Verificar el cumplimiento del mismo. En el caso que se hayan presentado incumplimientos al plan, solicitar los planes de mejora respectivos.
C34: FECHA SEGUIMIENTO | I34: SEGUIMIENTO A LA IMPLEMENTACIÓN
C35: 46360 | F35: Realizar plan de trabajo | I35: Diseñar y defenir un plan de trabajo para el cumplimiento del Sistema de Gestión SST, el cual debe tener los objetivos, metas, responsabilidades, recursos, cronograma de actividades, firmado por el empleador y el responsable del Sistema de Gestión de SST.
C36: RESPONSABLE | I36: Revisar que plan de trabajo se cumpla con lo establecido de acuerdo a lo planeado
C37: ='Tablero indicadores 2026'!G8 -> Líder Funcional SG SST

Sheet 3.
A1: PROCESOS ADMINISTRATIVOS / SEGURIDAD Y SALUD EN EL TRABAJO
A2: INDICADORES DE GESTION
A3: CODIGO | C3: RE-RH-37-SST | D3: NIVEL DE CLASIFICACIÓN | G3: USO INTERNO (NC2) | K3: VERSION | L3: 0.2
A5: NOMBRE DEL INDICADOR | E5: ='Tablero indicadores 2026'!B21 -> 3. Ejecución del plan de capacitaciòn
A7: PROCESO | E7: ='Tablero indicadores 2026'!A1 -> PROCESOS ADMINISTRATIVOS / SEGURIDAD Y SALUD EN EL TRABAJO | R7: META | T7: ='Tablero indicadores 2026'!L20 -> 0.9
A9: FORMULA | E9: ='Tablero indicadores 2026'!M7 -> SI/NO | R9: FRECUENCIA DE MEDICIÓN | T9: ='Tablero indicadores 2026'!H21 -> Semestral
A11: UNIDAD | E11: ='Tablero indicadores 2026'!I20 -> Porcentaje | R11: TIPO INDICADOR | T11: ='Tablero indicadores 2026'!A19 -> PROCESO
A13: RESPONSABLE MEDICIÓN | E13: ='Tablero indicadores 2026'!G7 -> Líder Funcional SG SST | R13: VIGENCIA | T13: 2026
